```cpp
std::vector<int> v(3);  // 크기가 3 인 벡터 만듦
std::cout << v.at(4);   // ??
```
위 경우, 크기가 3 인 `vector` 를 만들었지만 4 번째 원소를 요청하고 있다. 위와 같은 코드는 문법 상 아무 문제가 없는 코드이지만, 막상 실행하게 되면 오류가 발생하게 된다.

다른 예로 아래와 같이 큰 메모리를 할당하는 경우를 생각해봅시다.
```cpp
std::vector<int> v(1000000000);
// ?
```
우리가 사용하는 대부분의 시스템의 경우 위와 같이 큰 메모리를 할당할 수 없다. 따라서, 위 코드 역시 문법 상 틀린 것이 없는 코드이지만, 실제로 실행해보면 오류가 발생하게 된다.

이렇게 정상적인 상황에서 벗어난 모든 예외적인 상황들을 **예외(exception)** 라고 부른다.

## 기존의 예외 처리 방식

C 언어에서는 언어 차원에서 제공하는 예외 처리 방식이라는 것이 딱히 따로 존재하지 않았다. 따라서 아래와 같이, 어떤 작업을 실행한 뒤에 그 결과값을 확인하는 방식으로 처리했다. 예를 들어, 아래 [malloc](https://modoocode.com/243) 으로 메모리를 동적으로 할당하는 경우를 생각해보자.
```c
char *c = (char *)malloc(1000000000);
if (c == NULL) {
	printf("메모리 할당 오류!");
	return;
}
```
[malloc](https://modoocode.com/243) 의 경우 메모리 할당 실패시에 `NULL` 을 리턴하므로, 위와 같이 `c` 가 `NULL` 인지 확인함으로써 예외적인 상황을 처리할 수 있었다.

하지만 이러한 방식으로 예외를 처리한다면, 함수가 깊어지면 깊어질수록 꽤나 귀찮게 된다.
```c
bool func1(int *addr) {
	if (func2(addr)) {
		// Do something
	}
	return false;
}
bool func2(int *addr) {
	if (func3(addr)) {
		// Do something
	}
	return false;
}
bool func3(int *addr) {
	addr = (int *)malloc(100000000);
	if (addr == NULL) return false;
	return true;
}
int main() {
	int *addr;
	if (func1(addr)) {
		// 잘 처리됨
	} else {
		// 오류 발생
	}
}
```
위 코드의 경우 `func3` 에서 '예외가 발생할 수 있는 작업' 을 수행하는데, 만약에 예외가 발생하게 된다면 `false` 를 리턴하게 되고, 잘 처리 되었다면 `true` 를 리턴한다.

여기까지는 좋은데, 문제는 이 `func3` 가 `func2` 에서 호출되고, 다시 `func2` 는 `func1` 에서 호출되고, `func1` 은 `main` 에서 호출된다는 점이다. 만약에 `main` 의 입장에서 `func3` 에서 문제가 발생했을 때 이를 캐치하기 위해서는, 각각의 함수들에서 처리 결과를 모두 리턴해야 할 것이다.

위 코드는 예외가 `func3`에서만 발생해서 간단했지만, 만약에 `func2` 도 어떤 다른 작업을 해서 예외를 발생시킬 수 있다면 어떻게 해야 할까? 상당히 골치 아픈 일이다.

하지만 다행히 C++ 에서는 위와 같은 불편한 예외 처리 방식을 획기적으로 해결했다.

## 예외 발생시키기 - throw

C 언어에서는 예외가 발생했을 때, 다른 값을 리턴하는 것으로 예외를 처리했지만, C++ 에서는 예외가 발생했다는 사실을 명시적으로 나타낼 수 있다. 바로 `throw` 문을 사용하면 된다.

예를 들어, 아래와 같이 매우 간단한 `vector` 클래스를 생각해보자.
```cpp
template <typename T>
class Vector {
public:
	Vector(size_t size) : size_(size) {
		data_ = new T[size_];
		for (int i = 0; i < size_; i++) {
			data_[i] = 3;
		}
	}
	const T& at(size_t index) const {
		if (index >= size_) {
			throw out_of_range("vector 의 index가 범위를 초과했습니다.");
		}
		return data_[index];
	}
	~Vector() { delete[] data_; }

private:
	T* data_;
	size_t size_;
};
```
만들어진 `vector` 의 요청한 위치에 있는 원소를 리턴하는 함수인 `at` 함수를 생각해보자.

> [!NOTE]
> at 함수는 operator[] 와 같이 index 로 전달된 위치에 있는 원소를 리턴한다. 하지만 차이점으로, at 의 경우 const 객체를 리턴해서, 이를 변경할 수 없다.

인자로 전달된 `index` 가 범위 이내라면, 간단하게 `data[index]` 를 리턴하면 되겠지만, 범위 밖이라면 어떻게 해야 할까?

문제는 `at` 함수가 `const T&` 를 리턴하기 때문에, 따로 '오류 메세지' 를 리턴할 수 없다는 점이다. 하지만 C++ 에서는 다음과 같이 예외가 발생하였음을 명시적으로 알릴 수 있다.
```cpp
const T& at(size_t index) const {
	if (index >= size) {
		// 예외를 발생시킨다!
		throw std::out_of_range("vector 의 index 가 범위를 초과하였습니다.");
	}
	return data[index];
}
```
먼저, 예외를 발생시키는 부분을 자세히 살펴보자.
```cpp
throw std::out_of_range("vector 의 index 가 범위를 초과하였습니다.");
```
C++ 에는 예외를 던지고 싶다면, `throw` 로 예외로 전달하고 싶은 객체를 써주면 된다. 예외로 아무 객체나 던져도 상관 없지만, C++ 표준 라이브러리에는 이미 여러가지 종류의 예외들이 정의되어 있어서 이를 활용하는 것도 좋다. 예를 들어서, 위 경우 `out_of_range` 객체를 `throw` 한다. C++ 표준에는 `out_of_range` 외에도 `overflow_error, length_error, runtime_error` 등등 여러가지가 정의되어 있고 표준 라이브러리에서 활용되고 있다.

이렇게 예외를 `throw` 하게 되면, `throw` 한 위치에서 즉시 함수가 종료되고, 예외 처리하는 부분까지 점프하게 된다. 따라서 `throw` 밑에 있는 모든 문장은 실행되지 않는다. 한 가지 중요한 점은 이렇게 함수에서 예외 처리하는 부분에 도달하기까지 함수를 빠져나가면서, `stack` 에 생성되었던 객체들을 빠짐없이 소멸시켜 준다는 점이다. 따라서 예외가 발생해도 사용하고 있는 자원들을 제대로 소멸시킬 수 있다(소멸자만 제대로 작성했다면)!

## 예외 처리하기 - try/catch

그렇다면 이렇게 발생한 에외를 어떻게 처리할까?
```cpp
#include <iostream>
#include <stdexcept>

template <typename T>
class Vector {
public:
	Vector(size_t size) : size_(size) {
		data_ = new T[size_];
		for (int i = 0; i < size_; i++) {
			data_[i] = 3;
		}
	}
	const T& at(size_t index) const {
		if (index >= size_) {
			throw std::out_of_range("vector 의 index 가 범위를 초과하였습니다.");
		}
		return data_[index];
	}
	~Vector() { delete[] data_; }

private:
	T* data_;
	size_t size_;
};
int main() {
	Vector<int> vec(3);
	
	int index, data = 0;
	std::cin >> index;
	
	try {
		data = vec.at(index);
	} catch (std::out_of_range& e) {
		std::cout << "예외 발생 ! " << e.what() << std::endl;
	}
	// 예외가 발생하지 않았다면 3을 이 출력되고, 예외가 발생하였다면 원래 data 에
	// 들어가 있던 0 이 출력된다.
	std::cout << "읽은 데이터 : " << data << std::endl;
}
```
성공적으로 컴파일했다면
![[12.1.1.webp]]

위에서도 볼 수 있듯이, 범위에 벗어난 값 (위 경우 3 이상)을 입력하게 되었다면, 범위를 초과했다는 메세지를 볼 수 있다. 그렇다면, 예외가 어떤 식으로 처리되었는지 살펴보자.
```cpp
try {
	data = vec.at(index);
}
```
먼저 `try` 부분이다. `try` 안에서 무언가 예외가 발생할만한 코드가 실행된다. 만약에 예외가 발생하지 않았다면 마지 `try` .. `catch` 부분이 없는 것과 동일하게 실행된다. `data` 에는 `vec` 의 `index` 번째 값이 들어가고 밑에 있는 `catch` 문은 무시된다.

반면, 예외가 발생할 경우 이야기가 달라진다. 예외가 발생하게 되면, 그 즉시 `stack` 에 생성된 모든 객체들의 소멸자들이 호출되고, 가장 가까운 `catch` 문으로 점프한다. 따라서, 위 경우
```cpp
if (index >= size_) {
	throw std::out_of_range("vector 의 index 가 범위를 초과하였습니다.");
}
```
`throw` 다음으로 실행되는 문장이 바로
```cpp
catch (std::out_of_range& e) {
	std::cout << "예외 발생 ! " << e.what() << std::endl;
}
```
이 `catch` 부분이 된다. 여기서 `catch` 문은 `throw` 된 예외를 받는 부분인데, `catch` 문 안에 정의된 예외의 꼴에 맞는 객체를 받게 된다. 우리의 `Vector` 의 경우 `out_of_range` 를 `throw` 하였는데, 위 `catch` 문이 `out_of_range` 를 받으므로, 잘 받을 수 있다.

`out_of_range` 클래스는 아주 간단한데, 그냥 내부에 발생엔 예외에 관한 내용을 저장하는 문자열 필드가 달랑 하나 있고 이 역시 `what()` 함수로 그 값을 들여다 볼 수 있다. 위 경우 우리가 전달한 문장인 '`vector`의 `index`가 범위를 초과하였습니다' 가 나오게 된다.

## 스택 풀기 (stack unwinding)

앞서 `throw` 를 하게 된다면, 가장 가까운 `catch` 로 점프한다고 했다. 이 말의 뜻이 무엇인지 아래 예제로 살펴보자.
```cpp
#include <iostream>
#include <stdexcept>

class Resource {
public:
	Resource(int id) : id_(id) {}
	~Resource() { std::cout << "리소스 해제 : " << id_ << std::endl; }

private:
	int id_;
};

int func3() {
	Resource r(3);
	throw std::runtime_error("Exception from 3!\n");
}
int func2() {
	Resource r(2);
	func3();
	std::cout << "실행 안됨!" << std::endl;
	return 0;
}
int func1() {
	Resource r(1);
	func2();
	std::cout << "실행 안됨!" << std::endl;
	return 0;
}

int main() {
	try {
		func1();
	} catch (std::exception& e) {
		std::cout << "Exception : " << e.what();
	}
}
```
성공적으로 컴파일했으면
```
리소스 해제 : 3
리소스 해제 : 2
리소스 해제 : 1
Exception : Exception from 3!
```

```cpp
int func3() {
	Resource r(3);
	throw std::runtime_error("Exception from 3!\n");
}
```
에서 보다시피, `func3` 함수에서 예외를 발생시키고 있다. 그런데, 이 `func3`은 `func2`가 호출하고, `func2`는 `func1`이 호출하고, 마지막으로 `func1`은 `main`에서 호출된다.

앞에서 말했듯이 예외가 발생하게 되면 가장 가까운 `catch`에서 예외를 받는다고 했다. 그런데, `func1, 2` 모두 예외를 받는 `catch`구문이 없다. 따라서, 가장 가까운 `catch`부분은, `main`함수에 있는 `catch`구문이 되고, 실제로도 예외가 `main`함수까지 잘 전달되어서 출력되었다.

또 한 가지 중요한 점은, 예외가 전파되면서 각 함수들에 정의되어 있던 객체들이 잘 소멸되었다는 점이다.

먄약에 예외가 발생하지 않았을 경우 어떻게 나오게 되냐면
```cpp
#include <iostream>
#include <stdexcept>

class Resource {
public:
	Resource(int id) : id_(id) {}
	~Resource() { std::cout << "리소스 해제 : " << id_ << std::endl; }

private:
	int id_;
};

int func3() {
	Resource r(3);
	return 0;
}
int func2() {
	Resource r(2);
	func3();
	std::cout << "실행!" << std::endl;
	return 0;
}
int func1() {
	Resource r(1);
	func2();
	std::cout << "실행!" << std::endl;
	return 0;
}

int main() {
	try {
		func1();
	} catch (std::exception& e) {
		std::cout << "Exception : " << e.what();
	}
}
```
성공적으로 컴파일했다면
```
리소스 해제 : 3
실행!
리소스 해제 : 2
실행!
리소스 해제 : 1
```

위와 비교해보면, 정상적인 상황에서는 객체의 소멸자들은 함수가 종료될 때 호출되므로 "실행!" 이 먼저 출력되고, 그 뒤에 리소스 해제 되었다는 문장이 출력된다.

반면에 예외가 전파되는 과정에서는 바로 `catch`부분으로 점프하면서, 각 함수들에 있던 객체들만 해제하기 때문에 리소스 해제 되었다는 것은 정상적으로 출력되지만, 그 "실행 안됨!" 부분은 실행되지 않는다.

이와 같이 `catch`로 점프하면서 스택 상에서 정의된 객체들을 소멸시키는 과정을 스택 풀기(stack unwinding)라고 부른다.

> [!WARNING] 주의 사항
> 예외를 생성자에서 던질 때 주의해야 할 점이 하나 있다. 바로 생성자에서 예외가 발생 시, 소멸자가 호출되지 않는다는 점이다. 따라서, 만일 예외를 던지기 이전에 획득한 자원이 있다면 `catch` 에서 잘 해제시켜 줘야한다.

## 여러 종류의 예외 받기

앞서 `catch` 는 여러 종류의 예외를 받을 수 있다고 했다. 이를 위해선, 한 개의 `try` 안에 받고자 하는 모든 종류의 예외를 `catch` 문으로 주렁주렁 달면 된다.
```cpp
#include <iostream>
#include <string>

int func(int c) {
	if (c == 1) {
		throw 10;
	} else if (c == 2) {
		throw std::string("hi!");
	} else if (c == 3) {
		throw 'a';
	} else if (c == 4) {
		throw "hello!";
	}
	return 0;
}

int main() {
	int c;
	std::cin >> c;
	
	try {
		func(c);
	} catch (char x) {
		std::cout << "Char : " << x << std::endl;
	} catch (int x) {
		std::cout << "Int : " << x << std::endl;
	} catch (std::string& s) {
		std::cout << "String : " << s << std::endl;
	} catch (const char* s) {
		std::cout << "String Literal : " << s << std::endl;
	}
}
```
성공적으로 컴파일했다면
![[12.1.4.webp]]

마치 `switch` 문 처럼 `catch` 역시 여러 종류의 `throw` 된 객체를 모두 받을 수 있다. 위 경우,
```cpp
catch (char x) {
	std::cout << "Char : " << x << std::endl;
} catch (int x) {
	std::cout << "Int : " << x << std::endl;
} catch (std::string& s) {
	std::cout << "String : " << s << std::endl;
} catch (const char* s) {
	std::cout << "String Literal : " << s << std::endl;
}
```
첫번째 `catch` 문에서는 `char` 형 값을, 두 번째에서는 `int` 형 값을, 세 번째 에서는 [string](https://modoocode.com/237) 객체를, 마지막에서는 `const char*` 형 값을 받게 된다. 실제로도 각기 다른 값들을 `throw` 하였을 때, 작동하는 `catch` 가 달라지는 것을 확인할 수 있다.

또한 한 가지 흥미로운 점은, 기반 클래스와 파생 클래스의 경우 처리하는 방식이다.
```cpp
#include <exception>
#include <iostream>

class Parent : public std::exception {
 public:
  virtual const char* what() const noexcept override { return "Parent!\n"; }
};

class Child : public Parent {
 public:
  const char* what() const noexcept override { return "Child!\n"; }
};

int func(int c) {
  if (c == 1) {
    throw Parent();
  } else if (c == 2) {
    throw Child();
  }
  return 0;
}

int main() {
  int c;
  std::cin >> c;

  try {
    func(c);
  } catch (Parent& p) {
    std::cout << "Parent Catch!" << std::endl;
    std::cout << p.what();
  } catch (Child& c) {
    std::cout << "Child Catch!" << std::endl;
    std::cout << c.what();
  }
}
```